<?xml version="1.0"?>
<robot xmlns:xacro="http://ros.org/wiki/xacro">

    <link name="base_footprint" />

    <link name="base_link">
        <visual>
            <origin xyz="-0.032 0 0.0" rpy="0 0 0" />
            <geometry>
                <mesh filename="file://$(find robot_description)/meshes/base.stl"
                    scale="0.001 0.001 0.001" />
            </geometry>
            <material name="light_black" />
        </visual>

        <collision>
            <origin xyz="-0.032 0 0.000" rpy="0 0 0" />
            <geometry>
                <mesh filename="file://$(find robot_description)/meshes/base.stl"
                    scale="0.001 0.001 0.001" />
            </geometry>
        </collision>

        <inertial>
            <origin xyz="0 0 0" rpy="0 0 0" />
            <mass value="1" />
            <inertia ixx="2.2124416e-03" ixy="-1.2294101e-05" ixz="3.4938785e-05"
                iyy="2.1193702e-03" iyz="-5.0120904e-06" izz="2.0064271e-03" />
        </inertial>
    </link>

    <joint name="base_link_joint" type="fixed">
        <parent link="base_footprint" />
        <child link="base_link" />
        <origin xyz="0.0 0.0 0.010" rpy="0 0 0" />
    </joint>

    <joint name="wheel_left_joint" type="continuous">
        <parent link="base_link" />
        <child link="wheel_left_link" />
        <origin xyz="0.0 0.08 0.023" rpy="-1.57 0 0" />
        <axis xyz="0 0 1" />
        <limit effort="50000" velocity="10" />
        <dynamics damping="1.0" friction="1.0" />
    </joint>

    <link name="wheel_left_link">
        <visual>
            <origin xyz="0 0 0" rpy="1.57 0 0" />
            <geometry>
                <mesh filename="file://$(find robot_description)/meshes/left_wheel.stl"
                    scale="0.001 0.001 0.001" />
            </geometry>
            <material name="dark" />
        </visual>

        <collision>
            <origin xyz="0 0 0" rpy="0 0 0" />
            <geometry>
                <cylinder length="0.018" radius="0.033" />
            </geometry>
        </collision>

        <inertial>
            <origin xyz="0 0 0" />
            <mass value="2.8498940e-02" />
            <inertia ixx="1.1175580e-05" ixy="-4.2369783e-11" ixz="-5.9381719e-09"
                iyy="1.1192413e-05" iyz="-1.4400107e-11" izz="2.0712558e-05" />
        </inertial>
    </link>

    <joint name="wheel_right_joint" type="continuous">
        <parent link="base_link" />
        <child link="wheel_right_link" />
        <origin xyz="0.0 -0.080 0.023" rpy="-1.57 0 0" />
        <axis xyz="0 0 1" />
        <limit effort="50000" velocity="10" />
        <dynamics damping="1.0" friction="1.0" />
    </joint>

    <link name="wheel_right_link">
        <visual>
            <origin xyz="0 0 0" rpy="1.57 0 0" />
            <geometry>
                <mesh filename="file://$(find robot_description)/meshes/right_wheel.stl"
                    scale="0.001 0.001 0.001" />
            </geometry>
            <material name="dark" />
        </visual>

        <collision>
            <origin xyz="0 0 0" rpy="0 0 0" />
            <geometry>
                <cylinder length="0.018" radius="0.033" />
            </geometry>
        </collision>

        <inertial>
            <origin xyz="0 0 0" />
            <mass value="2.8498940e-02" />
            <inertia ixx="1.1175580e-05" ixy="-4.2369783e-11" ixz="-5.9381719e-09"
                iyy="1.1192413e-05" iyz="-1.4400107e-11" izz="2.0712558e-05" />
        </inertial>
    </link>

    <joint name="caster_back_joint" type="fixed">
        <parent link="base_link" />
        <child link="caster_back_link" />
        <origin xyz="-0.081 0 -0.004" rpy="-1.57 0 0" />
    </joint>

    <link name="caster_back_link">
        <collision>
            <origin xyz="0 0.001 0" rpy="0 0 0" />
            <geometry>
                <box size="0.01 0.01 0.01" />
            </geometry>
        </collision>

        <inertial>
            <origin xyz="0 0 0" />
            <mass value="0.010" />
            <inertia ixx="0.001" ixy="0.0" ixz="0.0" iyy="0.001" iyz="0.0" izz="0.001" />
        </inertial>
    </link>

    <xacro:if value="${simulation}">

        <xacro:arg name="namespace" default="" />

        <ros2_control name="GazeboSimSystem" type="system">
            <hardware>
                <plugin>gz_ros2_control/GazeboSimSystem</plugin>
            </hardware>
            <joint name="wheel_left_joint">
                <command_interface name="velocity">
                    <param name="min">-1</param>
                    <param name="max">1</param>
                </command_interface>
                <state_interface name="position" />
                <state_interface name="velocity" />
            </joint>
            <joint name="wheel_right_joint">
                <command_interface name="velocity">
                    <param name="min">-1</param>
                    <param name="max">1</param>
                </command_interface>
                <state_interface name="position" />
                <state_interface name="velocity" />
            </joint>
        </ros2_control>

        <gazebo>
            <plugin filename="gz_ros2_control-system"
                name="gz_ros2_control::GazeboSimROS2ControlPlugin">
                <ros>
                    <namespace>$(arg namespace)</namespace>
                </ros>
                <parameters>$(find robot_simulation)/config/diff_drive_controller.yaml</parameters>
            </plugin>
        </gazebo>

    </xacro:if>

</robot>